<mujoco model="g1_23dof_tray_holder">
  <compiler angle="radian" meshdir="meshes" />

  <!-- Visual-only XML: actual Stage-2 training reset pose baked into body transforms. Zero qpos shows the posed configuration. Not for normal dynamics/deploy use. --><option timestep="0.0005" iterations="100" integrator="RK4">
    <flag warmstart="enable" />
  </option>

  <default>
    <default class="contact">
      <geom contype="1" conaffinity="1" condim="3" solref="0.002 1" solimp="0.9 0.95 0.001" />
    </default>

    <default class="torso_motor">
      <joint damping="0.05" armature="0.01" frictionloss="0.2" />
    </default>
    <default class="leg_motor">
      <joint damping="0.05" armature="0.01" frictionloss="0.2" />
    </default>
    <default class="ankle_motor">
      <joint damping="0.05" armature="0.01" frictionloss="0.2" />
    </default>
    <default class="arm_motor">
      <joint damping="0.05" armature="0.01" frictionloss="0.2" />
    </default>
  </default>

  <asset>
    <mesh name="pelvis" file="pelvis.STL" />
    <mesh name="pelvis_contour_link" file="pelvis_contour_link.STL" />
    <mesh name="left_hip_pitch_link" file="left_hip_pitch_link.STL" />
    <mesh name="left_hip_roll_link" file="left_hip_roll_link.STL" />
    <mesh name="left_hip_yaw_link" file="left_hip_yaw_link.STL" />
    <mesh name="left_knee_link" file="left_knee_link.STL" />
    <mesh name="left_ankle_pitch_link" file="left_ankle_pitch_link.STL" />
    <mesh name="left_ankle_roll_link" file="left_ankle_roll_link.STL" />
    <mesh name="right_hip_pitch_link" file="right_hip_pitch_link.STL" />
    <mesh name="right_hip_roll_link" file="right_hip_roll_link.STL" />
    <mesh name="right_hip_yaw_link" file="right_hip_yaw_link.STL" />
    <mesh name="right_knee_link" file="right_knee_link.STL" />
    <mesh name="right_ankle_pitch_link" file="right_ankle_pitch_link.STL" />
    <mesh name="right_ankle_roll_link" file="right_ankle_roll_link.STL" />
    <mesh name="torso_link_23dof_rev_1_0" file="torso_link_23dof_rev_1_0.STL" />
    <mesh name="logo_link" file="logo_link.STL" />
    <mesh name="head_link" file="head_link.STL" />
    <mesh name="left_shoulder_pitch_link" file="left_shoulder_pitch_link.STL" />
    <mesh name="left_shoulder_roll_link" file="left_shoulder_roll_link.STL" />
    <mesh name="left_shoulder_yaw_link" file="left_shoulder_yaw_link.STL" />
    <mesh name="left_elbow_link" file="left_elbow_link.STL" />
    <mesh name="left_rubber_hand" file="left_rubber_hand.STL" />
    <mesh name="left_wrist_roll_rubber_hand" file="left_wrist_roll_rubber_hand.STL" />
    <mesh name="left_tray_holder_link_node__mesh_" file="tray_holder_side_left.stl" />
    <mesh name="right_shoulder_pitch_link" file="right_shoulder_pitch_link.STL" />
    <mesh name="right_shoulder_roll_link" file="right_shoulder_roll_link.STL" />
    <mesh name="right_shoulder_yaw_link" file="right_shoulder_yaw_link.STL" />
    <mesh name="right_elbow_link" file="right_elbow_link.STL" />
    <mesh name="right_rubber_hand" file="right_rubber_hand.STL" />
    <mesh name="right_wrist_roll_rubber_hand" file="right_wrist_roll_rubber_hand.STL" />
    <mesh name="right_tray_holder_link_node__mesh_" file="tray_holder_side_right.stl" />
  </asset>

  <worldbody>
    <body name="pelvis" pos="0.0000000000 0.0000000000 0.7930000000" quat="1.0000000000 0.0000000000 0.0000000000 0.0000000000">
      <inertial pos="0 0 -0.07605" quat="1 0 -0.000399148 0" mass="3.813" diaginertia="0.010549 0.0093089 0.0079184" />
      <joint name="floating_base_joint" type="free" limited="false" actuatorfrclimited="false" />
      <geom type="mesh" contype="0" conaffinity="0" group="1" density="0" rgba="0.2 0.2 0.2 1" mesh="pelvis" />
      <geom type="mesh" contype="0" conaffinity="0" group="1" density="0" rgba="0.7 0.7 0.7 1" mesh="pelvis_contour_link" />
      <geom type="mesh" rgba="0.7 0.7 0.7 1" mesh="pelvis_contour_link" />
      <site name="imu_in_pelvis" size="0.01" pos="0.04525 0 -0.08339" />
      <body name="left_hip_pitch_link" pos="0.0000000000 0.0644520000 -0.1027000000" quat="0.9987502604 0.0000000000 -0.0499791693 0.0000000000">
        <inertial pos="0.002741 0.047791 -0.02606" quat="0.954862 0.293964 0.0302556 0.030122" mass="1.35" diaginertia="0.00181517 0.00153422 0.00116212" />
        <joint name="left_hip_pitch_joint" pos="0 0 0" axis="0 1 0" range="-2.5307 2.8798" actuatorfrcrange="-88 88" class="leg_motor" />
        <geom type="mesh" contype="0" conaffinity="0" group="1" density="0" rgba="0.2 0.2 0.2 1" mesh="left_hip_pitch_link" />
        <geom type="mesh" rgba="0.2 0.2 0.2 1" mesh="left_hip_pitch_link" />
        <body name="left_hip_roll_link" pos="0.0000000000 0.0520000000 -0.0304650000" quat="0.9961786857 0.0000000000 -0.0873385724 0.0000000000">
          <inertial pos="0.029812 -0.001045 -0.087934" quat="0.977808 -1.97119e-05 0.205576 -0.0403793" mass="1.52" diaginertia="0.00254986 0.00241169 0.00148755" />
          <joint name="left_hip_roll_joint" pos="0 0 0" axis="1 0 0" range="-0.5236 2.9671" actuatorfrcrange="-139 139" class="leg_motor" />
          <geom type="mesh" contype="0" conaffinity="0" group="1" density="0" rgba="0.7 0.7 0.7 1" mesh="left_hip_roll_link" />
          <geom type="mesh" rgba="0.7 0.7 0.7 1" mesh="left_hip_roll_link" />
          <body name="left_hip_yaw_link" pos="0.0250010000 0.0000000000 -0.1241200000" quat="1.0000000000 0.0000000000 0.0000000000 0.0000000000">
            <inertial pos="-0.057709 -0.010981 -0.15078" quat="0.600598 0.15832 0.223482 0.751181" mass="1.702" diaginertia="0.00776166 0.00717575 0.00160139" />
            <joint name="left_hip_yaw_joint" pos="0 0 0" axis="0 0 1" range="-2.7576 2.7576" actuatorfrcrange="-88 88" class="leg_motor" />
            <geom type="mesh" contype="0" conaffinity="0" group="1" density="0" rgba="0.7 0.7 0.7 1" mesh="left_hip_yaw_link" />
            <geom type="mesh" rgba="0.7 0.7 0.7 1" mesh="left_hip_yaw_link" />
            <body name="left_knee_link" pos="-0.0782730000 0.0021489000 -0.1773400000" quat="0.9719409597 0.0000000000 0.2352249368 0.0000000000">
              <inertial pos="0.005457 0.003964 -0.12074" quat="0.923418 -0.0327699 0.0158246 0.382067" mass="1.932" diaginertia="0.0113804 0.0112778 0.00146458" />
              <joint name="left_knee_joint" pos="0 0 0" axis="0 1 0" range="-0.087267 2.8798" actuatorfrcrange="-139 139" class="leg_motor" />
              <geom type="mesh" contype="0" conaffinity="0" group="1" density="0" rgba="0.7 0.7 0.7 1" mesh="left_knee_link" />
              <geom type="mesh" rgba="0.7 0.7 0.7 1" mesh="left_knee_link" />
              <body name="left_ankle_pitch_link" pos="0.0000000000 -0.0000944450 -0.3000100000" quat="0.9950041653 0.0000000000 -0.0998334166 0.0000000000">
                <inertial pos="-0.007269 0 0.011137" quat="0.603053 0.369225 0.369225 0.603053" mass="0.074" diaginertia="1.89e-05 1.40805e-05 6.9195e-06" />
                <joint name="left_ankle_pitch_joint" pos="0 0 0" axis="0 1 0" range="-0.87267 0.5236" actuatorfrcrange="-50 50" class="ankle_motor" />
                <geom type="mesh" contype="0" conaffinity="0" group="1" density="0" rgba="0.7 0.7 0.7 1" mesh="left_ankle_pitch_link" />
                <geom type="mesh" rgba="0.7 0.7 0.7 1" mesh="left_ankle_pitch_link" />
                <body name="left_ankle_roll_link" pos="0.0000000000 0.0000000000 -0.0175580000" quat="1.0000000000 0.0000000000 0.0000000000 0.0000000000">
                  <inertial pos="0.026505 0 -0.016425" quat="-0.000481092 0.728482 -0.000618967 0.685065" mass="0.608" diaginertia="0.00167218 0.0016161 0.000217621" />
                  <joint name="left_ankle_roll_joint" pos="0 0 0" axis="1 0 0" range="-0.2618 0.2618" actuatorfrcrange="-50 50" class="ankle_motor" />
                  <geom type="mesh" contype="0" conaffinity="0" group="1" density="0" rgba="0.2 0.2 0.2 1" mesh="left_ankle_roll_link" />
                  <geom size="0.005" pos="-0.05 0.025 -0.03" rgba="0.2 0.2 0.2 1" />
                  <geom size="0.005" pos="-0.05 -0.025 -0.03" rgba="0.2 0.2 0.2 1" />
                  <geom size="0.005" pos="0.12 0.03 -0.03" rgba="0.2 0.2 0.2 1" />
                  <geom size="0.005" pos="0.12 -0.03 -0.03" rgba="0.2 0.2 0.2 1" />
                  <body name="left_toe_link" pos="0.1000000000 0.0000000000 -0.0200000000" quat="1.0000000000 0.0000000000 0.0000000000 0.0000000000" />
                </body>
              </body>
            </body>
          </body>
        </body>
      </body>
      <body name="pelvis_contour_link" pos="0.0000000000 0.0000000000 0.0000000000" quat="1.0000000000 0.0000000000 0.0000000000 0.0000000000" />
      <body name="right_hip_pitch_link" pos="0.0000000000 -0.0644520000 -0.1027000000" quat="0.9987502604 0.0000000000 -0.0499791693 0.0000000000">
        <inertial pos="0.002741 -0.047791 -0.02606" quat="0.954862 -0.293964 0.0302556 -0.030122" mass="1.35" diaginertia="0.00181517 0.00153422 0.00116212" />
        <joint name="right_hip_pitch_joint" pos="0 0 0" axis="0 1 0" range="-2.5307 2.8798" actuatorfrcrange="-88 88" class="leg_motor" />
        <geom type="mesh" contype="0" conaffinity="0" group="1" density="0" rgba="0.2 0.2 0.2 1" mesh="right_hip_pitch_link" />
        <geom type="mesh" rgba="0.2 0.2 0.2 1" mesh="right_hip_pitch_link" />
        <body name="right_hip_roll_link" pos="0.0000000000 -0.0520000000 -0.0304650000" quat="0.9961786857 0.0000000000 -0.0873385724 0.0000000000">
          <inertial pos="0.029812 0.001045 -0.087934" quat="0.977808 1.97119e-05 0.205576 0.0403793" mass="1.52" diaginertia="0.00254986 0.00241169 0.00148755" />
          <joint name="right_hip_roll_joint" pos="0 0 0" axis="1 0 0" range="-2.9671 0.5236" actuatorfrcrange="-139 139" class="leg_motor" />
          <geom type="mesh" contype="0" conaffinity="0" group="1" density="0" rgba="0.7 0.7 0.7 1" mesh="right_hip_roll_link" />
          <geom type="mesh" rgba="0.7 0.7 0.7 1" mesh="right_hip_roll_link" />
          <body name="right_hip_yaw_link" pos="0.0250010000 0.0000000000 -0.1241200000" quat="1.0000000000 0.0000000000 0.0000000000 0.0000000000">
            <inertial pos="-0.057709 0.010981 -0.15078" quat="0.751181 0.223482 0.15832 0.600598" mass="1.702" diaginertia="0.00776166 0.00717575 0.00160139" />
            <joint name="right_hip_yaw_joint" pos="0 0 0" axis="0 0 1" range="-2.7576 2.7576" actuatorfrcrange="-88 88" class="leg_motor" />
            <geom type="mesh" contype="0" conaffinity="0" group="1" density="0" rgba="0.7 0.7 0.7 1" mesh="right_hip_yaw_link" />
            <geom type="mesh" rgba="0.7 0.7 0.7 1" mesh="right_hip_yaw_link" />
            <body name="right_knee_link" pos="-0.0782730000 -0.0021489000 -0.1773400000" quat="0.9719409597 0.0000000000 0.2352249368 0.0000000000">
              <inertial pos="0.005457 -0.003964 -0.12074" quat="0.923439 0.0345276 0.0116333 -0.382012" mass="1.932" diaginertia="0.011374 0.0112843 0.00146452" />
              <joint name="right_knee_joint" pos="0 0 0" axis="0 1 0" range="-0.087267 2.8798" actuatorfrcrange="-139 139" class="leg_motor" />
              <geom type="mesh" contype="0" conaffinity="0" group="1" density="0" rgba="0.7 0.7 0.7 1" mesh="right_knee_link" />
              <geom type="mesh" rgba="0.7 0.7 0.7 1" mesh="right_knee_link" />
              <body name="right_ankle_pitch_link" pos="0.0000000000 0.0000944450 -0.3000100000" quat="0.9950041653 0.0000000000 -0.0998334166 0.0000000000">
                <inertial pos="-0.007269 0 0.011137" quat="0.603053 0.369225 0.369225 0.603053" mass="0.074" diaginertia="1.89e-05 1.40805e-05 6.9195e-06" />
                <joint name="right_ankle_pitch_joint" pos="0 0 0" axis="0 1 0" range="-0.87267 0.5236" actuatorfrcrange="-50 50" class="ankle_motor" />
                <geom type="mesh" contype="0" conaffinity="0" group="1" density="0" rgba="0.7 0.7 0.7 1" mesh="right_ankle_pitch_link" />
                <geom type="mesh" rgba="0.7 0.7 0.7 1" mesh="right_ankle_pitch_link" />
                <body name="right_ankle_roll_link" pos="0.0000000000 0.0000000000 -0.0175580000" quat="1.0000000000 0.0000000000 0.0000000000 0.0000000000">
                  <inertial pos="0.026505 0 -0.016425" quat="0.000481092 0.728482 0.000618967 0.685065" mass="0.608" diaginertia="0.00167218 0.0016161 0.000217621" />
                  <joint name="right_ankle_roll_joint" pos="0 0 0" axis="1 0 0" range="-0.2618 0.2618" actuatorfrcrange="-50 50" class="ankle_motor" />
                  <geom type="mesh" contype="0" conaffinity="0" group="1" density="0" rgba="0.2 0.2 0.2 1" mesh="right_ankle_roll_link" />
                  <geom size="0.005" pos="-0.05 0.025 -0.03" rgba="0.2 0.2 0.2 1" />
                  <geom size="0.005" pos="-0.05 -0.025 -0.03" rgba="0.2 0.2 0.2 1" />
                  <geom size="0.005" pos="0.12 0.03 -0.03" rgba="0.2 0.2 0.2 1" />
                  <geom size="0.005" pos="0.12 -0.03 -0.03" rgba="0.2 0.2 0.2 1" />
                  <body name="right_toe_link" pos="0.1000000000 0.0000000000 -0.0200000000" quat="1.0000000000 0.0000000000 0.0000000000 0.0000000000" />
                </body>
              </body>
            </body>
          </body>
        </body>
      </body>
      <body name="torso_link" pos="-0.0039635000 0.0000000000 0.0440000000" quat="1.0000000000 0.0000000000 0.0000000000 0.0000000000">
        <inertial pos="0.00203158 0.000339683 0.184568" quat="0.999803 -6.03319e-05 0.0198256 0.00131986" mass="7.818" diaginertia="0.121847 0.109825 0.0273735" />
        <joint name="waist_yaw_joint" pos="0 0 0" axis="0 0 1" range="-2.618 2.618" actuatorfrcrange="-88 88" class="torso_motor" />
        <site name="d435_camera_frame" pos="0.0576235 0.01753 0.42987" euler="0 0.8307767239493009 0" size="0.01" rgba="1 0 0 0.5" />
        <geom pos="0.0039635 0 -0.044" type="mesh" contype="0" conaffinity="0" group="1" density="0" rgba="0.7 0.7 0.7 1" mesh="torso_link_23dof_rev_1_0" />
        <geom pos="0.0039635 0 -0.044" type="mesh" rgba="0.7 0.7 0.7 1" mesh="torso_link_23dof_rev_1_0" />
        <geom pos="0.0039635 0 -0.044" quat="1 0 0 0" type="mesh" contype="0" conaffinity="0" group="1" density="0" rgba="0.2 0.2 0.2 1" mesh="logo_link" />
        <geom pos="0.0039635 0 -0.044" quat="1 0 0 0" type="mesh" rgba="0.2 0.2 0.2 1" mesh="logo_link" />
        <geom pos="0.0039635 0 -0.044" type="mesh" contype="0" conaffinity="0" group="1" density="0" rgba="0.2 0.2 0.2 1" mesh="head_link" />
        <geom pos="0.0039635 0 -0.044" type="mesh" rgba="0.2 0.2 0.2 1" mesh="head_link" />
        <body name="head_link" pos="0.0039635000 0.0000000000 -0.0440000000" quat="1.0000000000 0.0000000000 0.0000000000 0.0000000000">
          <inertial pos="0.0001 0.0001 0.0001" quat="1.0 0.0 0.0 0.0" mass="1.036" diaginertia="0.004 0.004 0.002" />
        </body>
        <body name="head_mocap" pos="0.0000000000 0.0000000000 0.4000000000" quat="1.0000000000 0.0000000000 0.0000000000 0.0000000000" />
        <site name="imu_in_torso" size="0.01" pos="-0.03959 -0.00224 0.14792" />
        <body name="imu_in_torso" pos="-0.0395900000 -0.0022400000 0.1479200000" quat="1.0000000000 0.0000000000 0.0000000000 0.0000000000" />
        <body name="left_shoulder_pitch_link" pos="0.0039563000 0.1002200000 0.2477800000" quat="0.9902641396 0.1392010196 0.0000138722 -0.0000986868">
          <inertial pos="0 0.035892 -0.011628" quat="0.654152 0.0130458 -0.326267 0.68225" mass="0.718" diaginertia="0.000465864 0.000432842 0.000406394" />
          <joint name="left_shoulder_pitch_joint" pos="0 0 0" axis="0 1 0" range="-3.0892 2.6704" actuatorfrcrange="-25 25" class="arm_motor" />
          <geom type="mesh" contype="0" conaffinity="0" group="1" density="0" rgba="0.7 0.7 0.7 1" mesh="left_shoulder_pitch_link" />
          <geom size="0.03 0.025" pos="0 0.04 -0.01" quat="0.707107 0 0.707107 0" type="cylinder" rgba="0.7 0.7 0.7 1" />
          <body name="left_shoulder_roll_link" pos="0.0000000000 0.0380000000 -0.0138310000" quat="0.9902682191 -0.1391720308 -0.0000000000 0.0000000000">
            <inertial pos="-0.000227 0.00727 -0.063243" quat="0.701256 -0.0196223 -0.00710317 0.712604" mass="0.643" diaginertia="0.000691311 0.000618011 0.000388977" />
            <joint name="left_shoulder_roll_joint" pos="0 0 0" axis="1 0 0" range="-1.5882 2.2515" actuatorfrcrange="-25 25" class="arm_motor" />
            <geom type="mesh" contype="0" conaffinity="0" group="1" density="0" rgba="0.7 0.7 0.7 1" mesh="left_shoulder_roll_link" />
            <geom size="0.03 0.015" pos="-0.004 0.006 -0.053" type="cylinder" rgba="0.7 0.7 0.7 1" />
            <body name="left_shoulder_yaw_link" pos="-0.0000000000 0.0062400000 -0.1032000000" quat="1.0000000000 0.0000000000 0.0000000000 0.0000000000">
              <inertial pos="0.010773 -0.002949 -0.072009" quat="0.716879 -0.0964829 -0.0679942 0.687134" mass="0.734" diaginertia="0.00106187 0.00103217 0.000400661" />
              <joint name="left_shoulder_yaw_joint" pos="0 0 0" axis="0 0 1" range="-2.618 2.618" actuatorfrcrange="-25 25" class="arm_motor" />
              <geom type="mesh" contype="0" conaffinity="0" group="1" density="0" rgba="0.7 0.7 0.7 1" mesh="left_shoulder_yaw_link" />
              <geom type="mesh" rgba="0.7 0.7 0.7 1" mesh="left_shoulder_yaw_link" />
              <body name="left_elbow_link" pos="0.0157830000 -0.0000000000 -0.0805180000" quat="1.0000000000 0.0000000000 0.0000000000 0.0000000000">
                <inertial pos="0.064956 0.004454 -0.010062" quat="0.541765 0.636132 0.388821 0.388129" mass="0.6" diaginertia="0.000443035 0.000421612 0.000259353" />
                <joint name="left_elbow_joint" pos="0 0 0" axis="0 1 0" range="-1.0472 2.0944" actuatorfrcrange="-25 25" class="arm_motor" />
                <geom type="mesh" contype="0" conaffinity="0" group="1" density="0" rgba="0.7 0.7 0.7 1" mesh="left_elbow_link" />
                <geom type="mesh" rgba="0.7 0.7 0.7 1" mesh="left_elbow_link" />
                <body name="left_wrist_roll_rubber_hand" pos="0.1000000000 0.0018879100 -0.0100000000" quat="1.0000000000 0.0000000000 0.0000000000 0.0000000000">
                  <inertial pos="0.107947 0.00163512 0.00202245" quat="0.494051 0.504265 0.48416 0.516933" mass="0.356929" diaginertia="0.00200292 0.0019426 0.000195232" />
                  <joint name="left_wrist_roll_joint" pos="0 0 0" axis="1 0 0" range="-1.97222 1.97222" actuatorfrcrange="-25 25" class="arm_motor" />
                  <geom type="mesh" contype="0" conaffinity="0" group="1" density="0" rgba="0.7 0.7 0.7 1" mesh="left_wrist_roll_rubber_hand" />
                  
                  
                      <body name="left_tray_holder_link" pos="0.1254958000 -0.0000038000 -0.0000005000" quat="1.0000000000 0.0000000000 0.0000000000 0.0000000000">
                        <geom quat="0.499951 -0.500077 0.499953 0.500019" type="mesh" contype="0" conaffinity="0" group="1" density="0" mesh="left_tray_holder_link_node__mesh_" />
                        <geom type="box" pos="0.0185042 0.0 0.0420005" size="0.10 0.08 0.002" rgba="0 0 0 1" friction="1.0 0.005 0.0001" />
                        <geom type="box" pos="0.0185042 0.0380038 0.0600005" size="0.1 0.0025 0.016" rgba="0 0 0 1" friction="1.0 0.005 0.0001" />
                        <geom type="box" pos="0.0185042 0.0200038 0.0680005" size="0.1 0.02 0.0025" rgba="0 0 0 1" friction="1.0 0.005 0.0001" />
                        <geom type="box" pos="-0.0784958 0.0150038 0.0600005" size="0.0025 0.02 0.016" rgba="0 0 0 1" friction="1.0 0.005 0.0001" />
                      </body>
                    
                </body>
              </body>
            </body>
          </body>
        </body>
        <body name="right_shoulder_pitch_link" pos="0.0039563000 -0.1002100000 0.2477800000" quat="0.9902641396 -0.1392010196 0.0000138722 0.0000986868">
          <inertial pos="0 -0.035892 -0.011628" quat="0.68225 -0.326267 0.0130458 0.654152" mass="0.718" diaginertia="0.000465864 0.000432842 0.000406394" />
          <joint name="right_shoulder_pitch_joint" pos="0 0 0" axis="0 1 0" range="-3.0892 2.6704" actuatorfrcrange="-25 25" class="arm_motor" />
          <geom type="mesh" contype="0" conaffinity="0" group="1" density="0" rgba="0.7 0.7 0.7 1" mesh="right_shoulder_pitch_link" />
          <geom size="0.03 0.025" pos="0 -0.04 -0.01" quat="0.707107 0 0.707107 0" type="cylinder" rgba="0.7 0.7 0.7 1" />
          <body name="right_shoulder_roll_link" pos="0.0000000000 -0.0380000000 -0.0138310000" quat="0.9902682191 0.1391720308 -0.0000000000 -0.0000000000">
            <inertial pos="-0.000227 -0.00727 -0.063243" quat="0.712604 -0.00710317 -0.0196223 0.701256" mass="0.643" diaginertia="0.000691311 0.000618011 0.000388977" />
            <joint name="right_shoulder_roll_joint" pos="0 0 0" axis="1 0 0" range="-2.2515 1.5882" actuatorfrcrange="-25 25" class="arm_motor" />
            <geom type="mesh" contype="0" conaffinity="0" group="1" density="0" rgba="0.7 0.7 0.7 1" mesh="right_shoulder_roll_link" />
            <geom size="0.03 0.015" pos="-0.004 -0.006 -0.053" type="cylinder" rgba="0.7 0.7 0.7 1" />
            <body name="right_shoulder_yaw_link" pos="-0.0000000000 -0.0062400000 -0.1032000000" quat="1.0000000000 0.0000000000 0.0000000000 0.0000000000">
              <inertial pos="0.010773 0.002949 -0.072009" quat="0.687134 -0.0679942 -0.0964829 0.716879" mass="0.734" diaginertia="0.00106187 0.00103217 0.000400661" />
              <joint name="right_shoulder_yaw_joint" pos="0 0 0" axis="0 0 1" range="-2.618 2.618" actuatorfrcrange="-25 25" class="arm_motor" />
              <geom type="mesh" contype="0" conaffinity="0" group="1" density="0" rgba="0.7 0.7 0.7 1" mesh="right_shoulder_yaw_link" />
              <geom type="mesh" rgba="0.7 0.7 0.7 1" mesh="right_shoulder_yaw_link" />
              <body name="right_elbow_link" pos="0.0157830000 0.0000000000 -0.0805180000" quat="1.0000000000 0.0000000000 0.0000000000 0.0000000000">
                <inertial pos="0.064956 -0.004454 -0.010062" quat="0.388129 0.388821 0.636132 0.541765" mass="0.6" diaginertia="0.000443035 0.000421612 0.000259353" />
                <joint name="right_elbow_joint" pos="0 0 0" axis="0 1 0" range="-1.0472 2.0944" actuatorfrcrange="-25 25" class="arm_motor" />
                <geom type="mesh" contype="0" conaffinity="0" group="1" density="0" rgba="0.7 0.7 0.7 1" mesh="right_elbow_link" />
                <geom type="mesh" rgba="0.7 0.7 0.7 1" mesh="right_elbow_link" />
                <body name="right_wrist_roll_rubber_hand" pos="0.1000000000 -0.0018879100 -0.0100000000" quat="1.0000000000 0.0000000000 0.0000000000 0.0000000000">
                  <inertial pos="0.107947 -0.00163512 0.00202245" quat="0.516933 0.48416 0.504265 0.494051" mass="0.356929" diaginertia="0.00200292 0.0019426 0.000195232" />
                  <joint name="right_wrist_roll_joint" pos="0 0 0" axis="1 0 0" range="-1.97222 1.97222" actuatorfrcrange="-25 25" class="arm_motor" />
                  <geom type="mesh" contype="0" conaffinity="0" group="1" density="0" rgba="0.7 0.7 0.7 1" mesh="right_wrist_roll_rubber_hand" />
                  
                  
                      <body name="right_tray_holder_link" pos="0.1254958000 0.0000038000 -0.0000005000" quat="1.0000000000 0.0000000000 0.0000000000 0.0000000000">
                        <geom quat="0.500077 -0.499951 0.500019 0.499953" type="mesh" contype="0" conaffinity="0" group="1" density="0" mesh="right_tray_holder_link_node__mesh_" />
                        <geom type="box" pos="0.0185042 -0.0000076 0.0420005" size="0.10 0.08 0.002" rgba="0 0 0 1" friction="1.0 0.005 0.0001" />
                        <geom type="box" pos="0.0185042 -0.0380038 0.0600005" size="0.1 0.0025 0.016" rgba="0 0 0 1" friction="1.0 0.005 0.0001" />
                        <geom type="box" pos="0.0185042 -0.0200038 0.0680005" size="0.1 0.02 0.0025" rgba="0 0 0 1" friction="1.0 0.005 0.0001" />
                        <geom type="box" pos="-0.0784958 -0.0150038 0.0600005" size="0.0025 0.02 0.016" rgba="0 0 0 1" friction="1.0 0.005 0.0001" />
                      </body>
                    
                </body>
              </body>
            </body>
          </body>
        </body>
      </body>
    </body>
  </worldbody>

  <actuator>
    <motor name="left_hip_pitch_joint" joint="left_hip_pitch_joint" ctrlrange="-88 88" />
    <motor name="left_hip_roll_joint" joint="left_hip_roll_joint" ctrlrange="-139 139" />
    <motor name="left_hip_yaw_joint" joint="left_hip_yaw_joint" ctrlrange="-88 88" />
    <motor name="left_knee_joint" joint="left_knee_joint" ctrlrange="-139 139" />
    <motor name="left_ankle_pitch_joint" joint="left_ankle_pitch_joint" ctrlrange="-50 50" />
    <motor name="left_ankle_roll_joint" joint="left_ankle_roll_joint" ctrlrange="-50 50" />
    <motor name="right_hip_pitch_joint" joint="right_hip_pitch_joint" ctrlrange="-88 88" />
    <motor name="right_hip_roll_joint" joint="right_hip_roll_joint" ctrlrange="-139 139" />
    <motor name="right_hip_yaw_joint" joint="right_hip_yaw_joint" ctrlrange="-88 88" />
    <motor name="right_knee_joint" joint="right_knee_joint" ctrlrange="-139 139" />
    <motor name="right_ankle_pitch_joint" joint="right_ankle_pitch_joint" ctrlrange="-50 50" />
    <motor name="right_ankle_roll_joint" joint="right_ankle_roll_joint" ctrlrange="-50 50" />
    <motor name="waist_yaw_joint" joint="waist_yaw_joint" ctrlrange="-88 88" />
    <motor name="left_shoulder_pitch_joint" joint="left_shoulder_pitch_joint" ctrlrange="-25 25" />
    <motor name="left_shoulder_roll_joint" joint="left_shoulder_roll_joint" ctrlrange="-25 25" />
    <motor name="left_shoulder_yaw_joint" joint="left_shoulder_yaw_joint" ctrlrange="-25 25" />
    <motor name="left_elbow_joint" joint="left_elbow_joint" ctrlrange="-25 25" />
    <motor name="left_wrist_roll_joint" joint="left_wrist_roll_joint" ctrlrange="-25 25" />
    <motor name="right_shoulder_pitch_joint" joint="right_shoulder_pitch_joint" ctrlrange="-25 25" />
    <motor name="right_shoulder_roll_joint" joint="right_shoulder_roll_joint" ctrlrange="-25 25" />
    <motor name="right_shoulder_yaw_joint" joint="right_shoulder_yaw_joint" ctrlrange="-25 25" />
    <motor name="right_elbow_joint" joint="right_elbow_joint" ctrlrange="-25 25" />
    <motor name="right_wrist_roll_joint" joint="right_wrist_roll_joint" ctrlrange="-25 25" />
  </actuator>

  <sensor>
    <gyro name="imu-torso-angular-velocity" site="imu_in_torso" noise="5e-4" cutoff="34.9" />
    <accelerometer name="imu-torso-linear-acceleration" site="imu_in_torso" noise="1e-2" cutoff="157" />
    <gyro name="imu-pelvis-angular-velocity" site="imu_in_pelvis" noise="5e-4" cutoff="34.9" />
    <accelerometer name="imu-pelvis-linear-acceleration" site="imu_in_pelvis" noise="1e-2" cutoff="157" />
  </sensor>


  
  <statistic center="1.0 0.7 1.0" extent="0.8" />
  <visual>
    <headlight diffuse="0.6 0.6 0.6" ambient="0.1 0.1 0.1" specular="0.9 0.9 0.9" />
    <rgba haze="0.15 0.25 0.35 1" />
    <global azimuth="-140" elevation="-20" />
  </visual>
  <asset>
    <texture type="skybox" builtin="flat" rgb1="0 0 0" rgb2="0 0 0" width="512" height="3072" />
    <texture type="2d" name="groundplane" builtin="checker" mark="edge" rgb1="0.2 0.3 0.4" rgb2="0.1 0.2 0.3" markrgb="0.8 0.8 0.8" width="300" height="300" />
    <material name="groundplane" texture="groundplane" texuniform="true" texrepeat="5 5" reflectance="0.2" />
  </asset>
  <worldbody>
    <light pos="1 0 3.5" dir="0 0 -1" directional="true" />
    <geom name="floor" size="0 0 0.05" type="plane" material="groundplane" />
    <body name="plate" pos="0.3022500000 0.0000000000 0.9340000000" quat="1.0000000000 0.0000000000 0.0000000000 0.0000000000">
      <geom name="plate_geom" type="box" size="0.127 0.176 0.008" rgba="1 0 0 1" mass="0.5" />
      <freejoint />
    </body>
    <body name="object" pos="0.3022500000 0.0000000000 1.0100000000" quat="1.0000000000 0.0000000000 0.0000000000 0.0000000000">
      <geom name="cup_wall" type="cylinder" size="0.025 0.05" rgba="0.8 0.8 0.8 1" mass="0.03" friction="0.6 0.005 0.0001" />
      <geom name="cup_bottom" type="cylinder" size="0.025 0.005" pos="0 0 -0.055" rgba="0.8 0.8 0.8 1" mass="0.015" />
      <geom name="liquid" type="cylinder" size="0.020 0.03" pos="0 0 -0.02" rgba="0.3 0.5 1 0.6" mass="0.055" contype="0" conaffinity="0" />
      <inertial pos="0 0 -0.015" mass="0.1" diaginertia="0.0003 0.0003 0.00008" />
      <freejoint />
    </body>
  </worldbody>
</mujoco>